Workbook

Sheet Data
A1: Make | B1: Model | C1: Overall Score | D1: Recommended | E1: Owner Satisfaction | F1: Overall Miles Per Gallon | G1: Acceleration (0-60) Sec
A2: Subaru | B2: Forester | C2: 84 | D2: Yes | E2: + | F2: 26 | G2: 8.7
A3: Honda | B3: CRV | C3: 83 | D3: Yes | E3: ++ | F3: 27 | G3: 8.6
A4: Toyota | B4: Rav4 | C4: 81 | D4: Yes | E4: ++ | F4: 24 | G4: 9.3
A5: Nissan | B5: Rogue | C5: 73 | D5: Yes | E5: + | F5: 24 | G5: 9.5
A6: Mazda | B6: CX-5 | C6: 71 | D6: Yes | E6: ++ | F6: 24 | G6: 8.6
A7: Kia | B7: Sportage | C7: 71 | D7: Yes | E7: + | F7: 23 | G7: 9.6
A8: Ford | B8: Escape | C8: 69 | D8: Yes | E8: 0 | F8: 23 | G8: 10.1
A9: Volkswagen | B9: Tiguan Limited | C9: 67 | D9: No | E9: 0 | F9: 21 | G9: 8.5
A10: Volkswagen | B10: Tiguan | C10: 65 | D10: No | E10: + | F10: 25 | G10: 10.3
A11: Mitsubishi | B11: Outlander | C11: 63 | D11: No | E11: 0 | F11: 24 | G11: 10
A12: Chevrolet | B12: Equinox | C12: 63 | D12: No | E12: 0 | F12: 31 | G12: 10.1
A13: Hyundai | B13: Tuscon | C13: 57 | D13: No | E13: 0 | F13: 26 | G13: 8.4
A14: GMC | B14: Terrain | C14: 57 | D14: No | E14: 0 | F14: 22 | G14: 7.2
A15: Jeep | B15: Cherokee | C15: 55 | D15: No | E15: - | F15: 22 | G15: 10.9
A16: Jeep | B16: Compass | C16: 50 | D16: No | E16: 0 | F16: 24 | G16: 9.8

Sheet Summary
A1: BMGT 240IS · Chapter 1 · compactsuv.xlsx — Summary
A2: Camm et al., Essentials of Modern Business Statistics with Microsoft Excel, 9e · Ch 1 — every figure is a live formula against the Data sheet, not a pasted value.
A4: DATA SET ANATOMY
A5: Elements (vehicles) | B5: =COUNTA(Data!B2:B16) -> 15 | C5: column B (Model) holds observation names
A6: Variables | B6: =COUNTA(Data!A1)+COUNTA(Data!C1:G1) -> 6 | C6: Make + the five measured columns; Model is the label | D6: Treating Make as part of the identifier instead gives 5 variables / 75 values — also defensible. Pick one and stay with it.
A7: Observations | B7: =B5 -> 15 | C7: a data set with n elements has n observations
A8: Data values | B8: =B5*B6 -> 90 | C8: elements x variables
A10: VARIABLE SUMMARY
A11: Variable | B11: Scale | C11: Categorical / quantitative | D11: Distinct | E11: Distribution in this file
A12: Make | B12: Nominal | C12: Categorical | D12: =SUMPRODUCT((Data!A2:A16<>"")/COUNTIF(Data!A2:A16,Data!A2:A16&"")) -> 13 | E12: ="13 makes across 15 vehicles — Volkswagen and Jeep appear twice" -> 13 makes across 15 vehicles — Volkswagen and Jeep appear twice
A13: Overall Score | B13: Interval | C13: Quantitative | D13: =SUMPRODUCT((Data!C2:C16<>"")/COUNTIF(Data!C2:C16,Data!C2:C16&"")) -> 12 | E13: =MIN(Data!C2:C16)&" to "&MAX(Data!C2:C16)&" · mean "&TEXT(AVERAGE(Data!C2:C16),"0.0") -> 50 to 84 · mean 67.3
A14: Recommended | B14: Nominal | C14: Categorical | D14: =SUMPRODUCT((Data!D2:D16<>"")/COUNTIF(Data!D2:D16,Data!D2:D16&"")) -> 2 | E14: ="Yes "&COUNTIF(Data!D2:D16,"Yes")&" · No "&COUNTIF(Data!D2:D16,"No") -> Yes 7 · No 8
A15: Owner Satisfaction | B15: Ordinal | C15: Categorical | D15: =SUMPRODUCT((Data!E2:E16<>"")/COUNTIF(Data!E2:E16,Data!E2:E16&"")) -> 4 | E15: ="++ "&COUNTIF(Data!E2:E16,"++")&" · + "&COUNTIF(Data!E2:E16,"+")&" · 0 "&COUNTIF(Data!E2:E16,0)&" · - "&COUNTIF(Data!E2:E16,"-") -> ++ 3 · + 4 · 0 7 · - 1
A16: Overall MPG | B16: Ratio | C16: Quantitative | D16: =SUMPRODUCT((Data!F2:F16<>"")/COUNTIF(Data!F2:F16,Data!F2:F16&"")) -> 8 | E16: =MIN(Data!F2:F16)&" to "&MAX(Data!F2:F16)&" mpg · mean "&TEXT(AVERAGE(Data!F2:F16),"0.0") -> 21 to 31 mpg · mean 24.4
A17: Acceleration 0-60 | B17: Ratio | C17: Quantitative | D17: =SUMPRODUCT((Data!G2:G16<>"")/COUNTIF(Data!G2:G16,Data!G2:G16&"")) -> 13 | E17: =MIN(Data!G2:G16)&" to "&MAX(Data!G2:G16)&" sec · mean "&TEXT(AVERAGE(Data!G2:G16),"0.00") -> 7.2 to 10.9 sec · mean 9.31
A19: THE THREE QUANTITATIVE VARIABLES
B20: Overall Score | C20: Overall MPG | D20: Acceleration
A21: n | B21: =COUNT(Data!C2:C16) -> 15 | C21: =COUNT(Data!F2:F16) -> 15 | D21: =COUNT(Data!G2:G16) -> 15
A22: Minimum | B22: =MIN(Data!C2:C16) -> 50 | C22: =MIN(Data!F2:F16) -> 21 | D22: =MIN(Data!G2:G16) -> 7.2
A23: Maximum | B23: =MAX(Data!C2:C16) -> 84 | C23: =MAX(Data!F2:F16) -> 31 | D23: =MAX(Data!G2:G16) -> 10.9
A24: Mean | B24: =AVERAGE(Data!C2:C16) -> 67.266667 | C24: =AVERAGE(Data!F2:F16) -> 24.4 | D24: =AVERAGE(Data!G2:G16) -> 9.3066667
A25: Median | B25: =MEDIAN(Data!C2:C16) -> 67 | C25: =MEDIAN(Data!F2:F16) -> 24 | D25: =MEDIAN(Data!G2:G16) -> 9.5
A26: Std deviation (sample) | B26: =_xludf.STDEV.S(Data!C2:C16) -> #NAME? | C26: =_xludf.STDEV.S(Data!F2:F16) -> #NAME? | D26: =_xludf.STDEV.S(Data!G2:G16) -> #NAME?
A28: WHICH ARITHMETIC IS LEGAL — the day-1 demo
A29: Ordinal scale — Excel answers anyway: | B29: =AVERAGE(Data!E2:E16) -> 0 | C29: returns a clean, WRONG 0 — no warning, no error
A30: How many cells it actually used: | B30: =COUNT(Data!E2:E16) -> 7 | C30: 7 numeric zeros
A31: How many cells are filled: | B31: =COUNTA(Data!E2:E16) -> 15 | C31: 15 — eight text cells were silently discarded. COUNT vs COUNTA is the only tell.
A33: 'RECOMMENDED' IS MANUFACTURED, NOT MEASURED
A34: Lowest score marked Yes | B34: =_xludf.MINIFS(Data!C2:C16,Data!D2:D16,"Yes") -> #NAME?
A35: Highest score marked No | B35: =_xludf.MAXIFS(Data!C2:C16,Data!D2:D16,"No") -> #NAME?
A36: Recommended is a threshold on Overall Score at roughly 68 — a categorical variable built by cutting a quantitative one. Who chose 68, and does it matter to the car at 57?
A38: WHERE DID EACH COLUMN COME FROM? (§1.3 — three ways to get data, one table)
A39: Column | C39: How it was obtained | D39: Book's category
A40: Overall MPG, Acceleration | C40: Consumer Reports drove the cars on a test track under controlled conditions | D40: experiment / controlled measurement
A41: Owner Satisfaction | C41: they surveyed people who already own one | D41: observational study — a survey
A42: Overall Score | C42: CR combined the measurements using weights of their own choosing | D42: constructed composite
A43: Recommended | C43: a threshold applied to Overall Score | D43: derived from another column
A44: Four columns, four different kinds of knowing — formatted identically, and Excel treats them all the same. Nothing in a spreadsheet tells you which is which.
A46: KEY TERMS — Camm 9e, Chapter 1 (definitions verbatim from the textbook)
A47: Term | B47: § | C47: Definition (Camm 9e) | D47: In this file
...
