Workbook

Sheet Data
A1: Nation | B1: WTO Status | C1: Per Capita GDP ($) | D1: Fitch Rating | E1: Fitch Outlook
A2: Armenia | B2: Member | C2: 4267 | D2: B+ | E2: Stable
A3: Australia | B3: Member | C3: 51812 | D3: AAA | E3: Negative
A4: Austria | B4: Member | C4: 48328 | D4: AA+ | E4: Stable
A5: Azerbaijan | B5: Observer | C5: 4214 | D5: BB+ | E5: Stable
A6: Bahrain | B6: Member | C6: 28608 | D6: B+ | E6: Stable
A7: Belgium | B7: Member | C7: 44594 | D7: AA- | E7: Negative
A8: Brazil | B8: Member | C8: 6797 | D8: BB- | E8: Negative
A9: Bulgaria | B9: Member | C9: 9976 | D9: BBB | E9: Positive
A10: Canada | B10: Member | C10: 43258 | D10: AA+ | E10: Stable
A11: Cape Verde | B11: Member | C11: 43258 | D11: B- | E11: Stable
A12: Chile | B12: Member | C12: 13232 | D12: A- | E12: Stable
A13: China | B13: Member | C13: 10500 | D13: A+ | E13: Stable
... A61: Vietnam | B61: Member | C61: 2786 | D61: BB | E61: Positive

Sheet Summary
A1: BMGT 240IS · Chapter 1 · nations.xlsx — Summary
A2: Camm et al., Essentials of Modern Business Statistics with Microsoft Excel, 9e · Ch 1 — every figure is a live formula against the Data sheet, not a pasted value.
A4: DATA SET ANATOMY
A5: Elements (nations) | B5: =COUNTA(Data!A2:A61) | C5: column A holds observation names, not data
A6: Variables | B6: =COUNTA(Data!B1:E1) | C6: B1:E1 — 'Nation' is a label, not a variable
A7: Observations | B7: =B5 | C7: a data set with n elements has n observations
A8: Data values | B8: =B5*B6 | C8: elements x variables
A10: VARIABLE SUMMARY
A11: Variable | B11: Scale | C11: Categorical / quantitative | D11: Distinct | E11: Distribution in this file
A12: WTO Status | B12: Nominal | C12: Categorical | D12: =SUMPRODUCT((Data!B2:B61<>"")/COUNTIF(Data!B2:B61,Data!B2:B61&"")) | E12: ="Member "&COUNTIF(Data!B2:B61,"Member")&" · Observer "&COUNTIF(Data!B2:B61,"Observer")
A13: Per Capita GDP ($) | B13: Ratio | C13: Quantitative | D13: =SUMPRODUCT((Data!C2:C61<>"")/COUNTIF(Data!C2:C61,Data!C2:C61&"")) | E13: ="$"&TEXT(MIN(Data!C2:C61),"#,##0")&" to $"&TEXT(MAX(Data!C2:C61),"#,##0")
A14: Fitch Rating | B14: Ordinal | C14: Categorical | D14: =SUMPRODUCT((Data!D2:D61<>"")/COUNTIF(Data!D2:D61,Data!D2:D61&"")) | E14: ="B- to AAA · AAA appears "&COUNTIF(Data!D2:D61,"AAA")&" times"
A15: Fitch Outlook | B15: Ordinal | C15: Categorical | D15: =SUMPRODUCT((Data!E2:E61<>"")/COUNTIF(Data!E2:E61,Data!E2:E61&"")) | E15: ="Stable "&COUNTIF(Data!E2:E61,"Stable")&" · Negative "&COUNTIF(Data!E2:E61,"Negative")&" · Positive "&COUNTIF(Data!E2:E61,"Positive")
A17: PER CAPITA GDP ($) — NUMERIC SUMMARY
A18: n | B18: =COUNT(Data!C2:C61) | C18: all 60 numeric — compare COUNT with COUNTA
A19: Minimum | B19: =MIN(Data!C2:C61) | C19: =INDEX(Data!A2:A61,MATCH(MIN(Data!C2:C61),Data!C2:C61,0))
A20: Maximum | B20: =MAX(Data!C2:C61) | C20: =INDEX(Data!A2:A61,MATCH(MAX(Data!C2:C61),Data!C2:C61,0))
A21: Mean | B21: =AVERAGE(Data!C2:C61)
A22: Median | B22: =MEDIAN(Data!C2:C61)
A23: Mean / median | B23: =B21/B22 | C23: above 1 = right-skewed; a few rich nations pull the mean up
A24: Nations above the mean | B24: =COUNTIF(Data!C2:C61,">"&B21) | C24: out of 60 — the mean is not 'the middle'
A25: Std deviation (sample) | B25: =STDEV.S(Data!C2:C61) | C25: course convention: .S variants
A27: WHICH ARITHMETIC IS LEGAL — the day-1 demo
A28: Ratio scale — the mean means something: | B28: =AVERAGE(Data!C2:C61)
A29: Ordinal scale — Excel refuses, loudly: | B29: =AVERAGE(Data!D2:D61) | C29: returns #DIV/0! — the column is entirely text, nothing to average
A30: The dangerous case does NOT error: | C30: in compactsuv.xlsx =AVERAGE(E2:E16) returns a clean, wrong 0 — seven numeric zeros averaged, eight text cells silently dropped
A32: DATA QUALITY FLAGS — errors present in the publisher file (§1.3, §1.9)
A33: Row | B33: Nation | C33: Problem | D33: How it is detectable
A34: =MATCH("CoStable Rica",Data!A1:A61,0) | B34: CoStable Rica | C34: Should read "Costa Rica" — a find-and-replace of "sta" to "Stable" hit column A. | D34: String scan; no outside knowledge needed
A35: =MATCH("South Korea",Data!A1:A61,0) | B35: South Korea | C35: GDP of $1,805 is wrong by roughly 17x; actual is near $31,600. | D35: Cross-column contradiction: an AA- nation cannot sit below Kenya
A36: =MATCH("Cape Verde",Data!A1:A61,0) | B36: Cape Verde | C36: GDP of $43,258 is wrong (actual near $3,000) and duplicates Canada exactly. | D36: Duplicate check: identical to the row above
A37: Each error needs a different technique — string scan, cross-column sanity check, duplicate check. That is a repeatable audit, on the textbook's own file.
A39: KEY TERMS — Camm 9e, Chapter 1 (definitions verbatim from the textbook)
A40: Term | B40: § | C40: Definition (Camm 9e) | D40: In this file
A41: Data | B41: §1.2 | C41: The facts and figures collected, analyzed, and summarized for presentation and interpretation.
A42: Elements | B42: §1.2 | C42: The entities on which data are collected. | D42: the 60 nations — rows 2:61
A43: Variable | B43: §1.2 | C43: A characteristic of interest for the elements. | D43: WTO Status, Per Capita GDP, Fitch Rating, Fitch Outlook (B1:E1)
A44: Data set | B44: §1.2 | C44: All the data collected in a particular study. | D44: 60 elements x 4 variables = 240 data values
A45: Observation | B45: §1.2 | C45: The set of measurements obtained for a particular element. | D45: one row — Armenia: Member, 4,267, B+, Stable
A46: Nominal scale | B46: §1.2 | C46: The scale of measurement for a variable when the data are labels or names used to identify an attribute of an element. Nominal data may be non-numeric or numeric. | D46: WTO Status — Member / Observer
...
